<?xml version="1.0"?>
<robot name="my_robot">

    <!-- Materials -->
    <material name="grey">
        <color rgba="0.7 0.7 0.7 1" />
    </material>
    <material name="green">
        <color rgba="0 0.6 0 1" />
    </material>
    <material name="white">
        <color rgba="1 1 1 1" />
    </material>

    <!-- Chassis -->
    <link name="base_link">
        <visual>
            <geometry>
                <cylinder radius="0.2" length="0.088" />
            </geometry>
            <origin xyz="0 0 0.069" rpy="0 0 0"/>
            <material name="green" />
        </visual>
    </link>

    <!-- LiDAR -->
    <link name="laser">
        <visual>
            <geometry>
                <cylinder radius="0.1" length="0.05" />
            </geometry>
            <origin xyz="0 0 0" rpy="0 0 0"/>
            <material name="white" />
        </visual>
    </link>

    <!-- Left Wheel -->
    <link name="left_wheel">
        <visual>
            <geometry>
                <cylinder radius="0.0325" length="0.026" />
            </geometry>
            <origin xyz="0 0 0" rpy="1.57 0 0"/>
            <material name="grey" />
        </visual>
    </link>

    <!-- Right Wheel -->
    <link name="right_wheel">
        <visual>
            <geometry>
                <cylinder radius="0.0325" length="0.026" />
            </geometry>
            <origin xyz="0 0 0" rpy="1.57 0 0"/>
            <material name="grey" />
        </visual>
    </link>

    <!-- Joints -->

    <!-- LiDAR fixed joint -->
    <joint name="base_lidar_joint" type="fixed">
        <parent link="base_link" />
        <child link="laser" />
        <origin xyz="0 0 0.138" rpy="0 0 0"/>
    </joint>

    <!-- Left wheel joint -->
    <joint name="base_left_wheel_joint" type="continuous">
        <parent link="base_link" />
        <child link="left_wheel" />
        <origin xyz="0 0.16 0.0225" rpy="0 0 0"/>
        <axis xyz="0 1 0" />
    </joint>

    <!-- Right wheel joint -->
    <joint name="base_right_wheel_joint" type="continuous">
        <parent link="base_link" />
        <child link="right_wheel" />
        <origin xyz="0 -0.16 0.0225" rpy="0 0 0"/>
        <axis xyz="0 1 0" />
    </joint>

    <!-- Base Footprint -->
<!-- <link name="base_footprint"/>
<joint name="base_footprint_joint" type="fixed">
  <parent link="base_link"/>
  <child link="base_footprint"/>
  <origin xyz="0 0 -0.069" rpy="0 0 0"/>
</joint> -->


</robot>

